{
    "PackageVulnerabilityID": "1",
    "DisclosureDate": "2020-08-03",
    "AffectedVersionRange": "*",
    "Summary": "Arbitrary Code Execution",
    "Contributor": {
        "Discloser": "",
        "Fixer": "n/a"
    },
    "Package": {
        "Registry": "pip",
        "Name": "pyyaml",
        "URL": "https://pypi.org/project/pyyaml",
        "Downloads": "8689456"
    },
    "CWEs": [
        {
            "ID": "94",
            "Description": ""
        }
    ],
    "CVSS": {
        "Version": "3.1",
        "AV": "N",
        "AC": "L",
        "PR": "N",
        "UI": "N",
        "S": "U",
        "C": "H",
        "I": "H",
        "A": "H",
        "E": "",
        "RL": "",
        "RC": "",
        "Score": "9.8"
    },
    "CVEs": [
        "CVE-2020-14343"
    ],
    "Repository": {
        "URL": "https://github.com/yaml/pyyaml",
        "Codebase": [
            "Python"
        ],
        "Owner": "yaml",
        "Name": "pyyaml",
        "Forks": "302",
        "Stars": "1375"
    },
    "Permalinks": [],
    "References": [
        {
            "Description": "GitHub Issue",
            "URL": "https://github.com/yaml/pyyaml/issues/420"
        },
        {
            "Description": "bugzilla.redhat.com",
            "URL": "https://bugzilla.redhat.com/show_bug.cgi?id=1860466"
        }
    ],
    "PrNumber": "1144"
}