{
    "PackageVulnerabilityID": "1",
    "DisclosureDate": "2021-01-28",
    "AffectedVersionRange": "*",
    "Summary": "Arbitrary Code Execution",
    "Contributor": {
        "Discloser": "43377443",
        "Fixer": ""
    },
    "Package": {
        "Registry": "pip",
        "Name": "datalab",
        "URL": "https://pypi.org/project/datalab",
        "Downloads": "7844"
    },
    "CWEs": [
        {
            "ID": "94",
            "Description": "Arbitrary Code Execution"
        }
    ],
    "CVSS": {
        "Version": "3.1",
        "AV": "P",
        "AC": "H",
        "PR": "L",
        "UI": "N",
        "S": "U",
        "C": "L",
        "I": "L",
        "A": "L",
        "E": "",
        "RL": "",
        "RC": "",
        "Score": "3.8"
    },
    "CVEs": [
        ""
    ],
    "Repository": {
        "URL": "https://github.com/googledatalab/pydatalab",
        "Codebase": [
            "Python"
        ],
        "Owner": "googledatalab",
        "Name": "pydatalab",
        "Forks": "80",
        "Stars": "185",
        "ForkName": "pydatalab"
    },
    "Permalinks": [
        "https://github.com/googledatalab/pydatalab/blob/1d6865237fdc8d184123d1e89193578da56d73b3/google/datalab/utils/commands/_utils.py#L332"
    ],
    "References": [
        {
            "Description": "",
            "URL": ""
        }
    ],
    "PrNumber": "1799",
    "FixSubmissionCount": 1
}